Using selector: EpollSelector
Using selector: EpollSelector
Using selector: EpollSelector
Using selector: EpollSelector
Using selector: EpollSelector
Using selector: EpollSelector
Using selector: EpollSelector
Using selector: EpollSelector
Internal Server Error: /
Traceback (most recent call last):
  File "/usr/local/lib/python3.6/site-packages/django/core/handlers/exception.py", line 34, in inner
    response = get_response(request)
  File "/usr/local/lib/python3.6/site-packages/django/core/handlers/base.py", line 100, in _get_response
    resolver_match = resolver.resolve(request.path_info)
  File "/usr/local/lib/python3.6/site-packages/django/urls/resolvers.py", line 544, in resolve
    for pattern in self.url_patterns:
  File "/usr/local/lib/python3.6/site-packages/django/utils/functional.py", line 48, in __get__
    res = instance.__dict__[self.name] = self.func(instance)
  File "/usr/local/lib/python3.6/site-packages/django/urls/resolvers.py", line 588, in url_patterns
    patterns = getattr(self.urlconf_module, "urlpatterns", self.urlconf_module)
  File "/usr/local/lib/python3.6/site-packages/django/utils/functional.py", line 48, in __get__
    res = instance.__dict__[self.name] = self.func(instance)
  File "/usr/local/lib/python3.6/site-packages/django/urls/resolvers.py", line 581, in urlconf_module
    return import_module(self.urlconf_name)
  File "/usr/local/lib/python3.6/importlib/__init__.py", line 126, in import_module
    return _bootstrap._gcd_import(name[level:], package, level)
  File "<frozen importlib._bootstrap>", line 994, in _gcd_import
  File "<frozen importlib._bootstrap>", line 971, in _find_and_load
  File "<frozen importlib._bootstrap>", line 955, in _find_and_load_unlocked
  File "<frozen importlib._bootstrap>", line 665, in _load_unlocked
  File "<frozen importlib._bootstrap_external>", line 678, in exec_module
  File "<frozen importlib._bootstrap>", line 219, in _call_with_frames_removed
  File "/app/manejar/urls.py", line 11, in <module>
    path('api/v1/area/', include('area.urls')),
  File "/usr/local/lib/python3.6/site-packages/django/urls/conf.py", line 34, in include
    urlconf_module = import_module(urlconf_module)
  File "/usr/local/lib/python3.6/importlib/__init__.py", line 126, in import_module
    return _bootstrap._gcd_import(name[level:], package, level)
  File "<frozen importlib._bootstrap>", line 994, in _gcd_import
  File "<frozen importlib._bootstrap>", line 971, in _find_and_load
  File "<frozen importlib._bootstrap>", line 955, in _find_and_load_unlocked
  File "<frozen importlib._bootstrap>", line 665, in _load_unlocked
  File "<frozen importlib._bootstrap_external>", line 678, in exec_module
  File "<frozen importlib._bootstrap>", line 219, in _call_with_frames_removed
  File "/app/area/urls.py", line 7, in <module>
    router.register(u'localidade/:id/areas', LocalidadeViewSet, basename='lista_areas')
TypeError: register() got an unexpected keyword argument 'basename'
Internal Server Error: /
Traceback (most recent call last):
  File "/usr/local/lib/python3.6/site-packages/django/core/handlers/exception.py", line 34, in inner
    response = get_response(request)
  File "/usr/local/lib/python3.6/site-packages/django/core/handlers/base.py", line 100, in _get_response
    resolver_match = resolver.resolve(request.path_info)
  File "/usr/local/lib/python3.6/site-packages/django/urls/resolvers.py", line 544, in resolve
    for pattern in self.url_patterns:
  File "/usr/local/lib/python3.6/site-packages/django/utils/functional.py", line 48, in __get__
    res = instance.__dict__[self.name] = self.func(instance)
  File "/usr/local/lib/python3.6/site-packages/django/urls/resolvers.py", line 588, in url_patterns
    patterns = getattr(self.urlconf_module, "urlpatterns", self.urlconf_module)
  File "/usr/local/lib/python3.6/site-packages/django/utils/functional.py", line 48, in __get__
    res = instance.__dict__[self.name] = self.func(instance)
  File "/usr/local/lib/python3.6/site-packages/django/urls/resolvers.py", line 581, in urlconf_module
    return import_module(self.urlconf_name)
  File "/usr/local/lib/python3.6/importlib/__init__.py", line 126, in import_module
    return _bootstrap._gcd_import(name[level:], package, level)
  File "<frozen importlib._bootstrap>", line 994, in _gcd_import
  File "<frozen importlib._bootstrap>", line 971, in _find_and_load
  File "<frozen importlib._bootstrap>", line 955, in _find_and_load_unlocked
  File "<frozen importlib._bootstrap>", line 665, in _load_unlocked
  File "<frozen importlib._bootstrap_external>", line 678, in exec_module
  File "<frozen importlib._bootstrap>", line 219, in _call_with_frames_removed
  File "/app/manejar/urls.py", line 11, in <module>
    path('api/v1/area/', include('area.urls')),
  File "/usr/local/lib/python3.6/site-packages/django/urls/conf.py", line 34, in include
    urlconf_module = import_module(urlconf_module)
  File "/usr/local/lib/python3.6/importlib/__init__.py", line 126, in import_module
    return _bootstrap._gcd_import(name[level:], package, level)
  File "<frozen importlib._bootstrap>", line 994, in _gcd_import
  File "<frozen importlib._bootstrap>", line 971, in _find_and_load
  File "<frozen importlib._bootstrap>", line 955, in _find_and_load_unlocked
  File "<frozen importlib._bootstrap>", line 665, in _load_unlocked
  File "<frozen importlib._bootstrap_external>", line 678, in exec_module
  File "<frozen importlib._bootstrap>", line 219, in _call_with_frames_removed
  File "/app/area/urls.py", line 7, in <module>
    router.register(u'localidade/:id/areas', LocalidadeViewSet, basename='lista_areas')
TypeError: register() got an unexpected keyword argument 'basename'
Internal Server Error: /favicon.ico
Traceback (most recent call last):
  File "/usr/local/lib/python3.6/site-packages/django/core/handlers/exception.py", line 34, in inner
    response = get_response(request)
  File "/usr/local/lib/python3.6/site-packages/django/utils/deprecation.py", line 93, in __call__
    response = self.process_request(request)
  File "/usr/local/lib/python3.6/site-packages/django/middleware/common.py", line 53, in process_request
    if self.should_redirect_with_slash(request):
  File "/usr/local/lib/python3.6/site-packages/django/middleware/common.py", line 71, in should_redirect_with_slash
    not is_valid_path(request.path_info, urlconf) and
  File "/usr/local/lib/python3.6/site-packages/django/urls/base.py", line 154, in is_valid_path
    resolve(path, urlconf)
  File "/usr/local/lib/python3.6/site-packages/django/urls/base.py", line 25, in resolve
    return get_resolver(urlconf).resolve(path)
  File "/usr/local/lib/python3.6/site-packages/django/urls/resolvers.py", line 544, in resolve
    for pattern in self.url_patterns:
  File "/usr/local/lib/python3.6/site-packages/django/utils/functional.py", line 48, in __get__
    res = instance.__dict__[self.name] = self.func(instance)
  File "/usr/local/lib/python3.6/site-packages/django/urls/resolvers.py", line 588, in url_patterns
    patterns = getattr(self.urlconf_module, "urlpatterns", self.urlconf_module)
  File "/usr/local/lib/python3.6/site-packages/django/utils/functional.py", line 48, in __get__
    res = instance.__dict__[self.name] = self.func(instance)
  File "/usr/local/lib/python3.6/site-packages/django/urls/resolvers.py", line 581, in urlconf_module
    return import_module(self.urlconf_name)
  File "/usr/local/lib/python3.6/importlib/__init__.py", line 126, in import_module
    return _bootstrap._gcd_import(name[level:], package, level)
  File "<frozen importlib._bootstrap>", line 994, in _gcd_import
  File "<frozen importlib._bootstrap>", line 971, in _find_and_load
  File "<frozen importlib._bootstrap>", line 955, in _find_and_load_unlocked
  File "<frozen importlib._bootstrap>", line 665, in _load_unlocked
  File "<frozen importlib._bootstrap_external>", line 678, in exec_module
  File "<frozen importlib._bootstrap>", line 219, in _call_with_frames_removed
  File "/app/manejar/urls.py", line 11, in <module>
    path('api/v1/area/', include('area.urls')),
  File "/usr/local/lib/python3.6/site-packages/django/urls/conf.py", line 34, in include
    urlconf_module = import_module(urlconf_module)
  File "/usr/local/lib/python3.6/importlib/__init__.py", line 126, in import_module
    return _bootstrap._gcd_import(name[level:], package, level)
  File "<frozen importlib._bootstrap>", line 994, in _gcd_import
  File "<frozen importlib._bootstrap>", line 971, in _find_and_load
  File "<frozen importlib._bootstrap>", line 955, in _find_and_load_unlocked
  File "<frozen importlib._bootstrap>", line 665, in _load_unlocked
  File "<frozen importlib._bootstrap_external>", line 678, in exec_module
  File "<frozen importlib._bootstrap>", line 219, in _call_with_frames_removed
  File "/app/area/urls.py", line 7, in <module>
    router.register(u'localidade/:id/areas', LocalidadeViewSet, basename='lista_areas')
TypeError: register() got an unexpected keyword argument 'basename'
Internal Server Error: /favicon.ico
Traceback (most recent call last):
  File "/usr/local/lib/python3.6/site-packages/django/core/handlers/exception.py", line 34, in inner
    response = get_response(request)
  File "/usr/local/lib/python3.6/site-packages/django/utils/deprecation.py", line 93, in __call__
    response = self.process_request(request)
  File "/usr/local/lib/python3.6/site-packages/django/middleware/common.py", line 53, in process_request
    if self.should_redirect_with_slash(request):
  File "/usr/local/lib/python3.6/site-packages/django/middleware/common.py", line 71, in should_redirect_with_slash
    not is_valid_path(request.path_info, urlconf) and
  File "/usr/local/lib/python3.6/site-packages/django/urls/base.py", line 154, in is_valid_path
    resolve(path, urlconf)
  File "/usr/local/lib/python3.6/site-packages/django/urls/base.py", line 25, in resolve
    return get_resolver(urlconf).resolve(path)
  File "/usr/local/lib/python3.6/site-packages/django/urls/resolvers.py", line 544, in resolve
    for pattern in self.url_patterns:
  File "/usr/local/lib/python3.6/site-packages/django/utils/functional.py", line 48, in __get__
    res = instance.__dict__[self.name] = self.func(instance)
  File "/usr/local/lib/python3.6/site-packages/django/urls/resolvers.py", line 588, in url_patterns
    patterns = getattr(self.urlconf_module, "urlpatterns", self.urlconf_module)
  File "/usr/local/lib/python3.6/site-packages/django/utils/functional.py", line 48, in __get__
    res = instance.__dict__[self.name] = self.func(instance)
  File "/usr/local/lib/python3.6/site-packages/django/urls/resolvers.py", line 581, in urlconf_module
    return import_module(self.urlconf_name)
  File "/usr/local/lib/python3.6/importlib/__init__.py", line 126, in import_module
    return _bootstrap._gcd_import(name[level:], package, level)
  File "<frozen importlib._bootstrap>", line 994, in _gcd_import
  File "<frozen importlib._bootstrap>", line 971, in _find_and_load
  File "<frozen importlib._bootstrap>", line 955, in _find_and_load_unlocked
  File "<frozen importlib._bootstrap>", line 665, in _load_unlocked
  File "<frozen importlib._bootstrap_external>", line 678, in exec_module
  File "<frozen importlib._bootstrap>", line 219, in _call_with_frames_removed
  File "/app/manejar/urls.py", line 11, in <module>
    path('api/v1/area/', include('area.urls')),
  File "/usr/local/lib/python3.6/site-packages/django/urls/conf.py", line 34, in include
    urlconf_module = import_module(urlconf_module)
  File "/usr/local/lib/python3.6/importlib/__init__.py", line 126, in import_module
    return _bootstrap._gcd_import(name[level:], package, level)
  File "<frozen importlib._bootstrap>", line 994, in _gcd_import
  File "<frozen importlib._bootstrap>", line 971, in _find_and_load
  File "<frozen importlib._bootstrap>", line 955, in _find_and_load_unlocked
  File "<frozen importlib._bootstrap>", line 665, in _load_unlocked
  File "<frozen importlib._bootstrap_external>", line 678, in exec_module
  File "<frozen importlib._bootstrap>", line 219, in _call_with_frames_removed
  File "/app/area/urls.py", line 7, in <module>
    router.register(u'localidade/:id/areas', LocalidadeViewSet, basename='lista_areas')
TypeError: register() got an unexpected keyword argument 'basename'
Using selector: EpollSelector
Using selector: EpollSelector
Using selector: EpollSelector
Using selector: EpollSelector
Internal Server Error: /admin/login/
Traceback (most recent call last):
  File "/usr/local/lib/python3.6/site-packages/django/db/backends/base/base.py", line 220, in ensure_connection
    self.connect()
  File "/usr/local/lib/python3.6/site-packages/django/utils/asyncio.py", line 26, in inner
    return func(*args, **kwargs)
  File "/usr/local/lib/python3.6/site-packages/django/db/backends/base/base.py", line 197, in connect
    self.connection = self.get_new_connection(conn_params)
  File "/usr/local/lib/python3.6/site-packages/django/utils/asyncio.py", line 26, in inner
    return func(*args, **kwargs)
  File "/usr/local/lib/python3.6/site-packages/django/db/backends/postgresql/base.py", line 185, in get_new_connection
    connection = Database.connect(**conn_params)
  File "/usr/local/lib/python3.6/site-packages/psycopg2/__init__.py", line 126, in connect
    conn = _connect(dsn, connection_factory=connection_factory, **kwasync)
psycopg2.OperationalError: FATAL:  database "plantio" does not exist


The above exception was the direct cause of the following exception:

Traceback (most recent call last):
  File "/usr/local/lib/python3.6/site-packages/django/core/handlers/exception.py", line 34, in inner
    response = get_response(request)
  File "/usr/local/lib/python3.6/site-packages/django/core/handlers/base.py", line 115, in _get_response
    response = self.process_exception_by_middleware(e, request)
  File "/usr/local/lib/python3.6/site-packages/django/core/handlers/base.py", line 113, in _get_response
    response = wrapped_callback(request, *callback_args, **callback_kwargs)
  File "/usr/local/lib/python3.6/site-packages/django/views/decorators/cache.py", line 44, in _wrapped_view_func
    response = view_func(request, *args, **kwargs)
  File "/usr/local/lib/python3.6/site-packages/django/contrib/admin/sites.py", line 407, in login
    return LoginView.as_view(**defaults)(request)
  File "/usr/local/lib/python3.6/site-packages/django/views/generic/base.py", line 71, in view
    return self.dispatch(request, *args, **kwargs)
  File "/usr/local/lib/python3.6/site-packages/django/utils/decorators.py", line 43, in _wrapper
    return bound_method(*args, **kwargs)
  File "/usr/local/lib/python3.6/site-packages/django/views/decorators/debug.py", line 76, in sensitive_post_parameters_wrapper
    return view(request, *args, **kwargs)
  File "/usr/local/lib/python3.6/site-packages/django/utils/decorators.py", line 43, in _wrapper
    return bound_method(*args, **kwargs)
  File "/usr/local/lib/python3.6/site-packages/django/utils/decorators.py", line 130, in _wrapped_view
    response = view_func(request, *args, **kwargs)
  File "/usr/local/lib/python3.6/site-packages/django/utils/decorators.py", line 43, in _wrapper
    return bound_method(*args, **kwargs)
  File "/usr/local/lib/python3.6/site-packages/django/views/decorators/cache.py", line 44, in _wrapped_view_func
    response = view_func(request, *args, **kwargs)
  File "/usr/local/lib/python3.6/site-packages/django/contrib/auth/views.py", line 63, in dispatch
    return super().dispatch(request, *args, **kwargs)
  File "/usr/local/lib/python3.6/site-packages/django/views/generic/base.py", line 97, in dispatch
    return handler(request, *args, **kwargs)
  File "/usr/local/lib/python3.6/site-packages/django/views/generic/edit.py", line 133, in get
    return self.render_to_response(self.get_context_data())
  File "/usr/local/lib/python3.6/site-packages/django/contrib/auth/views.py", line 97, in get_context_data
    current_site = get_current_site(self.request)
  File "/usr/local/lib/python3.6/site-packages/django/contrib/sites/shortcuts.py", line 13, in get_current_site
    return Site.objects.get_current(request)
  File "/usr/local/lib/python3.6/site-packages/django/contrib/sites/models.py", line 58, in get_current
    return self._get_site_by_id(site_id)
  File "/usr/local/lib/python3.6/site-packages/django/contrib/sites/models.py", line 30, in _get_site_by_id
    site = self.get(pk=site_id)
  File "/usr/local/lib/python3.6/site-packages/django/db/models/manager.py", line 82, in manager_method
    return getattr(self.get_queryset(), name)(*args, **kwargs)
  File "/usr/local/lib/python3.6/site-packages/django/db/models/query.py", line 411, in get
    num = len(clone)
  File "/usr/local/lib/python3.6/site-packages/django/db/models/query.py", line 258, in __len__
    self._fetch_all()
  File "/usr/local/lib/python3.6/site-packages/django/db/models/query.py", line 1261, in _fetch_all
    self._result_cache = list(self._iterable_class(self))
  File "/usr/local/lib/python3.6/site-packages/django/db/models/query.py", line 57, in __iter__
    results = compiler.execute_sql(chunked_fetch=self.chunked_fetch, chunk_size=self.chunk_size)
  File "/usr/local/lib/python3.6/site-packages/django/db/models/sql/compiler.py", line 1142, in execute_sql
    cursor = self.connection.cursor()
  File "/usr/local/lib/python3.6/site-packages/django/utils/asyncio.py", line 26, in inner
    return func(*args, **kwargs)
  File "/usr/local/lib/python3.6/site-packages/django/db/backends/base/base.py", line 260, in cursor
    return self._cursor()
  File "/usr/local/lib/python3.6/site-packages/django/db/backends/base/base.py", line 236, in _cursor
    self.ensure_connection()
  File "/usr/local/lib/python3.6/site-packages/django/utils/asyncio.py", line 26, in inner
    return func(*args, **kwargs)
  File "/usr/local/lib/python3.6/site-packages/django/db/backends/base/base.py", line 220, in ensure_connection
    self.connect()
  File "/usr/local/lib/python3.6/site-packages/django/db/utils.py", line 90, in __exit__
    raise dj_exc_value.with_traceback(traceback) from exc_value
  File "/usr/local/lib/python3.6/site-packages/django/db/backends/base/base.py", line 220, in ensure_connection
    self.connect()
  File "/usr/local/lib/python3.6/site-packages/django/utils/asyncio.py", line 26, in inner
    return func(*args, **kwargs)
  File "/usr/local/lib/python3.6/site-packages/django/db/backends/base/base.py", line 197, in connect
    self.connection = self.get_new_connection(conn_params)
  File "/usr/local/lib/python3.6/site-packages/django/utils/asyncio.py", line 26, in inner
    return func(*args, **kwargs)
  File "/usr/local/lib/python3.6/site-packages/django/db/backends/postgresql/base.py", line 185, in get_new_connection
    connection = Database.connect(**conn_params)
  File "/usr/local/lib/python3.6/site-packages/psycopg2/__init__.py", line 126, in connect
    conn = _connect(dsn, connection_factory=connection_factory, **kwasync)
django.db.utils.OperationalError: FATAL:  database "plantio" does not exist

Internal Server Error: /admin/login/
Traceback (most recent call last):
  File "/usr/local/lib/python3.6/site-packages/django/db/backends/base/base.py", line 220, in ensure_connection
    self.connect()
  File "/usr/local/lib/python3.6/site-packages/django/utils/asyncio.py", line 26, in inner
    return func(*args, **kwargs)
  File "/usr/local/lib/python3.6/site-packages/django/db/backends/base/base.py", line 197, in connect
    self.connection = self.get_new_connection(conn_params)
  File "/usr/local/lib/python3.6/site-packages/django/utils/asyncio.py", line 26, in inner
    return func(*args, **kwargs)
  File "/usr/local/lib/python3.6/site-packages/django/db/backends/postgresql/base.py", line 185, in get_new_connection
    connection = Database.connect(**conn_params)
  File "/usr/local/lib/python3.6/site-packages/psycopg2/__init__.py", line 126, in connect
    conn = _connect(dsn, connection_factory=connection_factory, **kwasync)
psycopg2.OperationalError: FATAL:  database "plantio" does not exist


The above exception was the direct cause of the following exception:

Traceback (most recent call last):
  File "/usr/local/lib/python3.6/site-packages/django/core/handlers/exception.py", line 34, in inner
    response = get_response(request)
  File "/usr/local/lib/python3.6/site-packages/django/core/handlers/base.py", line 115, in _get_response
    response = self.process_exception_by_middleware(e, request)
  File "/usr/local/lib/python3.6/site-packages/django/core/handlers/base.py", line 113, in _get_response
    response = wrapped_callback(request, *callback_args, **callback_kwargs)
  File "/usr/local/lib/python3.6/site-packages/django/views/decorators/cache.py", line 44, in _wrapped_view_func
    response = view_func(request, *args, **kwargs)
  File "/usr/local/lib/python3.6/site-packages/django/contrib/admin/sites.py", line 407, in login
    return LoginView.as_view(**defaults)(request)
  File "/usr/local/lib/python3.6/site-packages/django/views/generic/base.py", line 71, in view
    return self.dispatch(request, *args, **kwargs)
  File "/usr/local/lib/python3.6/site-packages/django/utils/decorators.py", line 43, in _wrapper
    return bound_method(*args, **kwargs)
  File "/usr/local/lib/python3.6/site-packages/django/views/decorators/debug.py", line 76, in sensitive_post_parameters_wrapper
    return view(request, *args, **kwargs)
  File "/usr/local/lib/python3.6/site-packages/django/utils/decorators.py", line 43, in _wrapper
    return bound_method(*args, **kwargs)
  File "/usr/local/lib/python3.6/site-packages/django/utils/decorators.py", line 130, in _wrapped_view
    response = view_func(request, *args, **kwargs)
  File "/usr/local/lib/python3.6/site-packages/django/utils/decorators.py", line 43, in _wrapper
    return bound_method(*args, **kwargs)
  File "/usr/local/lib/python3.6/site-packages/django/views/decorators/cache.py", line 44, in _wrapped_view_func
    response = view_func(request, *args, **kwargs)
  File "/usr/local/lib/python3.6/site-packages/django/contrib/auth/views.py", line 63, in dispatch
    return super().dispatch(request, *args, **kwargs)
  File "/usr/local/lib/python3.6/site-packages/django/views/generic/base.py", line 97, in dispatch
    return handler(request, *args, **kwargs)
  File "/usr/local/lib/python3.6/site-packages/django/views/generic/edit.py", line 133, in get
    return self.render_to_response(self.get_context_data())
  File "/usr/local/lib/python3.6/site-packages/django/contrib/auth/views.py", line 97, in get_context_data
    current_site = get_current_site(self.request)
  File "/usr/local/lib/python3.6/site-packages/django/contrib/sites/shortcuts.py", line 13, in get_current_site
    return Site.objects.get_current(request)
  File "/usr/local/lib/python3.6/site-packages/django/contrib/sites/models.py", line 58, in get_current
    return self._get_site_by_id(site_id)
  File "/usr/local/lib/python3.6/site-packages/django/contrib/sites/models.py", line 30, in _get_site_by_id
    site = self.get(pk=site_id)
  File "/usr/local/lib/python3.6/site-packages/django/db/models/manager.py", line 82, in manager_method
    return getattr(self.get_queryset(), name)(*args, **kwargs)
  File "/usr/local/lib/python3.6/site-packages/django/db/models/query.py", line 411, in get
    num = len(clone)
  File "/usr/local/lib/python3.6/site-packages/django/db/models/query.py", line 258, in __len__
    self._fetch_all()
  File "/usr/local/lib/python3.6/site-packages/django/db/models/query.py", line 1261, in _fetch_all
    self._result_cache = list(self._iterable_class(self))
  File "/usr/local/lib/python3.6/site-packages/django/db/models/query.py", line 57, in __iter__
    results = compiler.execute_sql(chunked_fetch=self.chunked_fetch, chunk_size=self.chunk_size)
  File "/usr/local/lib/python3.6/site-packages/django/db/models/sql/compiler.py", line 1142, in execute_sql
    cursor = self.connection.cursor()
  File "/usr/local/lib/python3.6/site-packages/django/utils/asyncio.py", line 26, in inner
    return func(*args, **kwargs)
  File "/usr/local/lib/python3.6/site-packages/django/db/backends/base/base.py", line 260, in cursor
    return self._cursor()
  File "/usr/local/lib/python3.6/site-packages/django/db/backends/base/base.py", line 236, in _cursor
    self.ensure_connection()
  File "/usr/local/lib/python3.6/site-packages/django/utils/asyncio.py", line 26, in inner
    return func(*args, **kwargs)
  File "/usr/local/lib/python3.6/site-packages/django/db/backends/base/base.py", line 220, in ensure_connection
    self.connect()
  File "/usr/local/lib/python3.6/site-packages/django/db/utils.py", line 90, in __exit__
    raise dj_exc_value.with_traceback(traceback) from exc_value
  File "/usr/local/lib/python3.6/site-packages/django/db/backends/base/base.py", line 220, in ensure_connection
    self.connect()
  File "/usr/local/lib/python3.6/site-packages/django/utils/asyncio.py", line 26, in inner
    return func(*args, **kwargs)
  File "/usr/local/lib/python3.6/site-packages/django/db/backends/base/base.py", line 197, in connect
    self.connection = self.get_new_connection(conn_params)
  File "/usr/local/lib/python3.6/site-packages/django/utils/asyncio.py", line 26, in inner
    return func(*args, **kwargs)
  File "/usr/local/lib/python3.6/site-packages/django/db/backends/postgresql/base.py", line 185, in get_new_connection
    connection = Database.connect(**conn_params)
  File "/usr/local/lib/python3.6/site-packages/psycopg2/__init__.py", line 126, in connect
    conn = _connect(dsn, connection_factory=connection_factory, **kwasync)
django.db.utils.OperationalError: FATAL:  database "plantio" does not exist

Internal Server Error: /admin/login/
Traceback (most recent call last):
  File "/usr/local/lib/python3.6/site-packages/django/db/backends/base/base.py", line 220, in ensure_connection
    self.connect()
  File "/usr/local/lib/python3.6/site-packages/django/utils/asyncio.py", line 26, in inner
    return func(*args, **kwargs)
  File "/usr/local/lib/python3.6/site-packages/django/db/backends/base/base.py", line 197, in connect
    self.connection = self.get_new_connection(conn_params)
  File "/usr/local/lib/python3.6/site-packages/django/utils/asyncio.py", line 26, in inner
    return func(*args, **kwargs)
  File "/usr/local/lib/python3.6/site-packages/django/db/backends/postgresql/base.py", line 185, in get_new_connection
    connection = Database.connect(**conn_params)
  File "/usr/local/lib/python3.6/site-packages/psycopg2/__init__.py", line 126, in connect
    conn = _connect(dsn, connection_factory=connection_factory, **kwasync)
psycopg2.OperationalError: FATAL:  database "plantio" does not exist


The above exception was the direct cause of the following exception:

Traceback (most recent call last):
  File "/usr/local/lib/python3.6/site-packages/django/core/handlers/exception.py", line 34, in inner
    response = get_response(request)
  File "/usr/local/lib/python3.6/site-packages/django/core/handlers/base.py", line 115, in _get_response
    response = self.process_exception_by_middleware(e, request)
  File "/usr/local/lib/python3.6/site-packages/django/core/handlers/base.py", line 113, in _get_response
    response = wrapped_callback(request, *callback_args, **callback_kwargs)
  File "/usr/local/lib/python3.6/site-packages/django/views/decorators/cache.py", line 44, in _wrapped_view_func
    response = view_func(request, *args, **kwargs)
  File "/usr/local/lib/python3.6/site-packages/django/contrib/admin/sites.py", line 407, in login
    return LoginView.as_view(**defaults)(request)
  File "/usr/local/lib/python3.6/site-packages/django/views/generic/base.py", line 71, in view
    return self.dispatch(request, *args, **kwargs)
  File "/usr/local/lib/python3.6/site-packages/django/utils/decorators.py", line 43, in _wrapper
    return bound_method(*args, **kwargs)
  File "/usr/local/lib/python3.6/site-packages/django/views/decorators/debug.py", line 76, in sensitive_post_parameters_wrapper
    return view(request, *args, **kwargs)
  File "/usr/local/lib/python3.6/site-packages/django/utils/decorators.py", line 43, in _wrapper
    return bound_method(*args, **kwargs)
  File "/usr/local/lib/python3.6/site-packages/django/utils/decorators.py", line 130, in _wrapped_view
    response = view_func(request, *args, **kwargs)
  File "/usr/local/lib/python3.6/site-packages/django/utils/decorators.py", line 43, in _wrapper
    return bound_method(*args, **kwargs)
  File "/usr/local/lib/python3.6/site-packages/django/views/decorators/cache.py", line 44, in _wrapped_view_func
    response = view_func(request, *args, **kwargs)
  File "/usr/local/lib/python3.6/site-packages/django/contrib/auth/views.py", line 63, in dispatch
    return super().dispatch(request, *args, **kwargs)
  File "/usr/local/lib/python3.6/site-packages/django/views/generic/base.py", line 97, in dispatch
    return handler(request, *args, **kwargs)
  File "/usr/local/lib/python3.6/site-packages/django/views/generic/edit.py", line 133, in get
    return self.render_to_response(self.get_context_data())
  File "/usr/local/lib/python3.6/site-packages/django/contrib/auth/views.py", line 97, in get_context_data
    current_site = get_current_site(self.request)
  File "/usr/local/lib/python3.6/site-packages/django/contrib/sites/shortcuts.py", line 13, in get_current_site
    return Site.objects.get_current(request)
  File "/usr/local/lib/python3.6/site-packages/django/contrib/sites/models.py", line 58, in get_current
    return self._get_site_by_id(site_id)
  File "/usr/local/lib/python3.6/site-packages/django/contrib/sites/models.py", line 30, in _get_site_by_id
    site = self.get(pk=site_id)
  File "/usr/local/lib/python3.6/site-packages/django/db/models/manager.py", line 82, in manager_method
    return getattr(self.get_queryset(), name)(*args, **kwargs)
  File "/usr/local/lib/python3.6/site-packages/django/db/models/query.py", line 411, in get
    num = len(clone)
  File "/usr/local/lib/python3.6/site-packages/django/db/models/query.py", line 258, in __len__
    self._fetch_all()
  File "/usr/local/lib/python3.6/site-packages/django/db/models/query.py", line 1261, in _fetch_all
    self._result_cache = list(self._iterable_class(self))
  File "/usr/local/lib/python3.6/site-packages/django/db/models/query.py", line 57, in __iter__
    results = compiler.execute_sql(chunked_fetch=self.chunked_fetch, chunk_size=self.chunk_size)
  File "/usr/local/lib/python3.6/site-packages/django/db/models/sql/compiler.py", line 1142, in execute_sql
    cursor = self.connection.cursor()
  File "/usr/local/lib/python3.6/site-packages/django/utils/asyncio.py", line 26, in inner
    return func(*args, **kwargs)
  File "/usr/local/lib/python3.6/site-packages/django/db/backends/base/base.py", line 260, in cursor
    return self._cursor()
  File "/usr/local/lib/python3.6/site-packages/django/db/backends/base/base.py", line 236, in _cursor
    self.ensure_connection()
  File "/usr/local/lib/python3.6/site-packages/django/utils/asyncio.py", line 26, in inner
    return func(*args, **kwargs)
  File "/usr/local/lib/python3.6/site-packages/django/db/backends/base/base.py", line 220, in ensure_connection
    self.connect()
  File "/usr/local/lib/python3.6/site-packages/django/db/utils.py", line 90, in __exit__
    raise dj_exc_value.with_traceback(traceback) from exc_value
  File "/usr/local/lib/python3.6/site-packages/django/db/backends/base/base.py", line 220, in ensure_connection
    self.connect()
  File "/usr/local/lib/python3.6/site-packages/django/utils/asyncio.py", line 26, in inner
    return func(*args, **kwargs)
  File "/usr/local/lib/python3.6/site-packages/django/db/backends/base/base.py", line 197, in connect
    self.connection = self.get_new_connection(conn_params)
  File "/usr/local/lib/python3.6/site-packages/django/utils/asyncio.py", line 26, in inner
    return func(*args, **kwargs)
  File "/usr/local/lib/python3.6/site-packages/django/db/backends/postgresql/base.py", line 185, in get_new_connection
    connection = Database.connect(**conn_params)
  File "/usr/local/lib/python3.6/site-packages/psycopg2/__init__.py", line 126, in connect
    conn = _connect(dsn, connection_factory=connection_factory, **kwasync)
django.db.utils.OperationalError: FATAL:  database "plantio" does not exist

Internal Server Error: /admin/login/
Traceback (most recent call last):
  File "/usr/local/lib/python3.6/site-packages/django/db/backends/base/base.py", line 220, in ensure_connection
    self.connect()
  File "/usr/local/lib/python3.6/site-packages/django/utils/asyncio.py", line 26, in inner
    return func(*args, **kwargs)
  File "/usr/local/lib/python3.6/site-packages/django/db/backends/base/base.py", line 197, in connect
    self.connection = self.get_new_connection(conn_params)
  File "/usr/local/lib/python3.6/site-packages/django/utils/asyncio.py", line 26, in inner
    return func(*args, **kwargs)
  File "/usr/local/lib/python3.6/site-packages/django/db/backends/postgresql/base.py", line 185, in get_new_connection
    connection = Database.connect(**conn_params)
  File "/usr/local/lib/python3.6/site-packages/psycopg2/__init__.py", line 126, in connect
    conn = _connect(dsn, connection_factory=connection_factory, **kwasync)
psycopg2.OperationalError: FATAL:  database "plantio" does not exist


The above exception was the direct cause of the following exception:

Traceback (most recent call last):
  File "/usr/local/lib/python3.6/site-packages/django/core/handlers/exception.py", line 34, in inner
    response = get_response(request)
  File "/usr/local/lib/python3.6/site-packages/django/core/handlers/base.py", line 115, in _get_response
    response = self.process_exception_by_middleware(e, request)
  File "/usr/local/lib/python3.6/site-packages/django/core/handlers/base.py", line 113, in _get_response
    response = wrapped_callback(request, *callback_args, **callback_kwargs)
  File "/usr/local/lib/python3.6/site-packages/django/views/decorators/cache.py", line 44, in _wrapped_view_func
    response = view_func(request, *args, **kwargs)
  File "/usr/local/lib/python3.6/site-packages/django/contrib/admin/sites.py", line 407, in login
    return LoginView.as_view(**defaults)(request)
  File "/usr/local/lib/python3.6/site-packages/django/views/generic/base.py", line 71, in view
    return self.dispatch(request, *args, **kwargs)
  File "/usr/local/lib/python3.6/site-packages/django/utils/decorators.py", line 43, in _wrapper
    return bound_method(*args, **kwargs)
  File "/usr/local/lib/python3.6/site-packages/django/views/decorators/debug.py", line 76, in sensitive_post_parameters_wrapper
    return view(request, *args, **kwargs)
  File "/usr/local/lib/python3.6/site-packages/django/utils/decorators.py", line 43, in _wrapper
    return bound_method(*args, **kwargs)
  File "/usr/local/lib/python3.6/site-packages/django/utils/decorators.py", line 130, in _wrapped_view
    response = view_func(request, *args, **kwargs)
  File "/usr/local/lib/python3.6/site-packages/django/utils/decorators.py", line 43, in _wrapper
    return bound_method(*args, **kwargs)
  File "/usr/local/lib/python3.6/site-packages/django/views/decorators/cache.py", line 44, in _wrapped_view_func
    response = view_func(request, *args, **kwargs)
  File "/usr/local/lib/python3.6/site-packages/django/contrib/auth/views.py", line 63, in dispatch
    return super().dispatch(request, *args, **kwargs)
  File "/usr/local/lib/python3.6/site-packages/django/views/generic/base.py", line 97, in dispatch
    return handler(request, *args, **kwargs)
  File "/usr/local/lib/python3.6/site-packages/django/views/generic/edit.py", line 133, in get
    return self.render_to_response(self.get_context_data())
  File "/usr/local/lib/python3.6/site-packages/django/contrib/auth/views.py", line 97, in get_context_data
    current_site = get_current_site(self.request)
  File "/usr/local/lib/python3.6/site-packages/django/contrib/sites/shortcuts.py", line 13, in get_current_site
    return Site.objects.get_current(request)
  File "/usr/local/lib/python3.6/site-packages/django/contrib/sites/models.py", line 58, in get_current
    return self._get_site_by_id(site_id)
  File "/usr/local/lib/python3.6/site-packages/django/contrib/sites/models.py", line 30, in _get_site_by_id
    site = self.get(pk=site_id)
  File "/usr/local/lib/python3.6/site-packages/django/db/models/manager.py", line 82, in manager_method
    return getattr(self.get_queryset(), name)(*args, **kwargs)
  File "/usr/local/lib/python3.6/site-packages/django/db/models/query.py", line 411, in get
    num = len(clone)
  File "/usr/local/lib/python3.6/site-packages/django/db/models/query.py", line 258, in __len__
    self._fetch_all()
  File "/usr/local/lib/python3.6/site-packages/django/db/models/query.py", line 1261, in _fetch_all
    self._result_cache = list(self._iterable_class(self))
  File "/usr/local/lib/python3.6/site-packages/django/db/models/query.py", line 57, in __iter__
    results = compiler.execute_sql(chunked_fetch=self.chunked_fetch, chunk_size=self.chunk_size)
  File "/usr/local/lib/python3.6/site-packages/django/db/models/sql/compiler.py", line 1142, in execute_sql
    cursor = self.connection.cursor()
  File "/usr/local/lib/python3.6/site-packages/django/utils/asyncio.py", line 26, in inner
    return func(*args, **kwargs)
  File "/usr/local/lib/python3.6/site-packages/django/db/backends/base/base.py", line 260, in cursor
    return self._cursor()
  File "/usr/local/lib/python3.6/site-packages/django/db/backends/base/base.py", line 236, in _cursor
    self.ensure_connection()
  File "/usr/local/lib/python3.6/site-packages/django/utils/asyncio.py", line 26, in inner
    return func(*args, **kwargs)
  File "/usr/local/lib/python3.6/site-packages/django/db/backends/base/base.py", line 220, in ensure_connection
    self.connect()
  File "/usr/local/lib/python3.6/site-packages/django/db/utils.py", line 90, in __exit__
    raise dj_exc_value.with_traceback(traceback) from exc_value
  File "/usr/local/lib/python3.6/site-packages/django/db/backends/base/base.py", line 220, in ensure_connection
    self.connect()
  File "/usr/local/lib/python3.6/site-packages/django/utils/asyncio.py", line 26, in inner
    return func(*args, **kwargs)
  File "/usr/local/lib/python3.6/site-packages/django/db/backends/base/base.py", line 197, in connect
    self.connection = self.get_new_connection(conn_params)
  File "/usr/local/lib/python3.6/site-packages/django/utils/asyncio.py", line 26, in inner
    return func(*args, **kwargs)
  File "/usr/local/lib/python3.6/site-packages/django/db/backends/postgresql/base.py", line 185, in get_new_connection
    connection = Database.connect(**conn_params)
  File "/usr/local/lib/python3.6/site-packages/psycopg2/__init__.py", line 126, in connect
    conn = _connect(dsn, connection_factory=connection_factory, **kwasync)
django.db.utils.OperationalError: FATAL:  database "plantio" does not exist

